<?xml version="1.0"?>
<robot xmlns:xacro="http://ros.org/wiki/xacro">

<xacro:arg name="robot_name" default="abb_irb1200_5_90"/>

<xacro:macro name="abb_irb1200_5_90" params="robot_name parent">
	<joint name="${parent}_${robot_name}_joint" type="fixed">
		<insert_block name="origin"/>
		<parent link="${parent}"/>
		<child link="${robot_name}_link"/>
	</joint>

	<!-- link list -->
	<link name="${robot_name}_link">
		<visual name="visual">
			<geometry>
				<mesh filename="package://picking_vision/meshes/irb1200_5_90/visual/base_link.dae"/>
			</geometry>
		</visual>
	</link>

	<joint type="revolute" name="${robot_name}joint_1">
		<origin xyz="0 0 0.3991" rpy="0 0 0"/>
		<axis xyz="0 0 1"/>
		<parent link="${robot_name}_link"/>
		<child link="${robot_name}link_1"/>
		<limit effort="1000" lower="-2.967" upper="2.967" velocity="5.027"/>
	</joint>

	<link name="${robot_name}link_1">
		<visual name="visual">
			<geometry>
				<mesh filename="package://picking_vision/meshes/irb1200_5_90/visual/link_1.dae"/>
			</geometry>
		</visual>
    </link>

	<joint type="revolute" name="${robot_name}joint_2">
		<origin xyz="0 0 0" rpy="0 0 0"/>
		<axis xyz="0 1 0"/>
		<parent link="${robot_name}link_1"/>
		<child link="${robot_name}link_2"/>
		<limit effort="1000" lower="-1.745" upper="2.269" velocity="4.189"/>
	</joint>

	<link name="${robot_name}link_2">
		<visual name="visual">
			<geometry>
				<mesh filename="package://picking_vision/meshes/irb1200_5_90/visual/link_2.dae"/>
			</geometry>
		</visual>
	</link>

	<joint type="revolute" name="${robot_name}joint_3">
		<origin xyz="0 0 0.448" rpy="0 0 0"/>
		<axis xyz="0 1 0"/>
		<parent link="${robot_name}link_2"/>
		<child link="${robot_name}link_3"/>
		<limit effort="1000" lower="-3.491" upper="1.222" velocity="5.236"/>
	</joint>

	<link name="${robot_name}link_3">
		<visual name="visual">
			<geometry>
				<mesh filename="package://picking_vision/meshes/irb1200_5_90/visual/link_3.dae"/>
			</geometry>
		</visual>
	</link>

	<joint type="revolute" name="${robot_name}joint_4">
		<origin xyz="0 0 0.042" rpy="0 0 0"/>
		<axis xyz="1 0 0"/>
		<parent link="${robot_name}link_3"/>
		<child link="${robot_name}link_4"/>
		<limit effort="1000" lower="-4.712" upper="4.712" velocity="6.981"/>
	</joint>

	<link name="${robot_name}link_4">
		<visual name="visual">
			<geometry>
			<mesh filename="package://picking_vision/meshes/irb1200_5_90/visual/link_4.dae"/>
			</geometry>
		</visual>
	</link>

	<joint type="revolute" name="${robot_name}joint_5">
		<origin xyz="0.451 0 0" rpy="0 0 0"/>
		<axis xyz="0 1 0"/>
		<parent link="${robot_name}link_4"/>
		<child link="${robot_name}link_5"/>
		<limit effort="1000" lower="-2.269" upper="2.269" velocity="7.069"/>
	</joint>

	<link name="${robot_name}link_5">
		<visual name="visual">
			<geometry>
				<mesh filename="package://picking_vision/meshes/irb1200_5_90/visual/link_5.dae"/>
			</geometry>
		</visual>
	</link>

	<joint type="revolute" name="${robot_name}joint_6">
		<origin xyz="0.082 0 0" rpy="0 0 0"/>
		<axis xyz="1 0 0"/>
		<parent link="${robot_name}link_5"/>
		<child link="${robot_name}link_6"/>
		<limit effort="1000" lower="-6.283" upper="6.283" velocity="10.472"/>
	</joint>

	<link name="${robot_name}link_6">
		<visual name="visual">
			<geometry>
				<mesh filename="package://picking_vision/meshes/irb1200_5_90/visual/link_6.dae"/>
			</geometry>
		</visual>
	</link>

</xacro:macro>

</robot>